2020-07-16 11:25:25,525 INFO: Microblog startup [in /Users/skedzie/Development/learn/python/microblog/app/__init__.py:44]
2020-07-16 11:50:21,747 INFO: Microblog startup [in /Users/skedzie/Development/learn/python/microblog/app/__init__.py:44]
2020-07-16 21:49:15,103 INFO: Microblog startup [in /Users/skedzie/Development/learn/python/microblog/app/__init__.py:46]
2020-07-16 21:52:39,605 INFO: Microblog startup [in /Users/skedzie/Development/learn/python/microblog/app/__init__.py:46]
2020-07-16 21:54:17,589 INFO: Microblog startup [in /Users/skedzie/Development/learn/python/microblog/app/__init__.py:46]
2020-07-16 22:07:36,438 INFO: Microblog startup [in /Users/skedzie/Development/learn/python/microblog/app/__init__.py:46]
2020-07-16 22:08:44,259 INFO: Microblog startup [in /Users/skedzie/Development/learn/python/microblog/app/__init__.py:46]
2020-07-16 22:23:28,598 INFO: Microblog startup [in /Users/skedzie/Development/learn/python/microblog/app/__init__.py:46]
2020-07-16 22:23:33,954 ERROR: Exception on /user/steve [GET] [in /Users/skedzie/Development/learn/python/microblog/venv/lib/python3.8/site-packages/flask/app.py:1891]
Traceback (most recent call last):
  File "/Users/skedzie/Development/learn/python/microblog/venv/lib/python3.8/site-packages/flask/app.py", line 2447, in wsgi_app
    response = self.full_dispatch_request()
  File "/Users/skedzie/Development/learn/python/microblog/venv/lib/python3.8/site-packages/flask/app.py", line 1952, in full_dispatch_request
    rv = self.handle_user_exception(e)
  File "/Users/skedzie/Development/learn/python/microblog/venv/lib/python3.8/site-packages/flask/app.py", line 1821, in handle_user_exception
    reraise(exc_type, exc_value, tb)
  File "/Users/skedzie/Development/learn/python/microblog/venv/lib/python3.8/site-packages/flask/_compat.py", line 39, in reraise
    raise value
  File "/Users/skedzie/Development/learn/python/microblog/venv/lib/python3.8/site-packages/flask/app.py", line 1950, in full_dispatch_request
    rv = self.dispatch_request()
  File "/Users/skedzie/Development/learn/python/microblog/venv/lib/python3.8/site-packages/flask/app.py", line 1936, in dispatch_request
    return self.view_functions[rule.endpoint](**req.view_args)
  File "/Users/skedzie/Development/learn/python/microblog/venv/lib/python3.8/site-packages/flask_login/utils.py", line 272, in decorated_view
    return func(*args, **kwargs)
  File "/Users/skedzie/Development/learn/python/microblog/app/routes.py", line 87, in user_profile
    raise NameError
NameError
2020-07-16 22:25:01,775 ERROR: Exception on /user/steve [GET] [in /Users/skedzie/Development/learn/python/microblog/venv/lib/python3.8/site-packages/flask/app.py:1891]
Traceback (most recent call last):
  File "/Users/skedzie/Development/learn/python/microblog/venv/lib/python3.8/site-packages/flask/app.py", line 2447, in wsgi_app
    response = self.full_dispatch_request()
  File "/Users/skedzie/Development/learn/python/microblog/venv/lib/python3.8/site-packages/flask/app.py", line 1952, in full_dispatch_request
    rv = self.handle_user_exception(e)
  File "/Users/skedzie/Development/learn/python/microblog/venv/lib/python3.8/site-packages/flask/app.py", line 1821, in handle_user_exception
    reraise(exc_type, exc_value, tb)
  File "/Users/skedzie/Development/learn/python/microblog/venv/lib/python3.8/site-packages/flask/_compat.py", line 39, in reraise
    raise value
  File "/Users/skedzie/Development/learn/python/microblog/venv/lib/python3.8/site-packages/flask/app.py", line 1950, in full_dispatch_request
    rv = self.dispatch_request()
  File "/Users/skedzie/Development/learn/python/microblog/venv/lib/python3.8/site-packages/flask/app.py", line 1936, in dispatch_request
    return self.view_functions[rule.endpoint](**req.view_args)
  File "/Users/skedzie/Development/learn/python/microblog/venv/lib/python3.8/site-packages/flask_login/utils.py", line 272, in decorated_view
    return func(*args, **kwargs)
  File "/Users/skedzie/Development/learn/python/microblog/app/routes.py", line 87, in user_profile
    raise NameError
NameError
2020-07-16 22:25:40,368 ERROR: Exception on /user/steve [GET] [in /Users/skedzie/Development/learn/python/microblog/venv/lib/python3.8/site-packages/flask/app.py:1891]
Traceback (most recent call last):
  File "/Users/skedzie/Development/learn/python/microblog/venv/lib/python3.8/site-packages/flask/app.py", line 2447, in wsgi_app
    response = self.full_dispatch_request()
  File "/Users/skedzie/Development/learn/python/microblog/venv/lib/python3.8/site-packages/flask/app.py", line 1952, in full_dispatch_request
    rv = self.handle_user_exception(e)
  File "/Users/skedzie/Development/learn/python/microblog/venv/lib/python3.8/site-packages/flask/app.py", line 1821, in handle_user_exception
    reraise(exc_type, exc_value, tb)
  File "/Users/skedzie/Development/learn/python/microblog/venv/lib/python3.8/site-packages/flask/_compat.py", line 39, in reraise
    raise value
  File "/Users/skedzie/Development/learn/python/microblog/venv/lib/python3.8/site-packages/flask/app.py", line 1950, in full_dispatch_request
    rv = self.dispatch_request()
  File "/Users/skedzie/Development/learn/python/microblog/venv/lib/python3.8/site-packages/flask/app.py", line 1936, in dispatch_request
    return self.view_functions[rule.endpoint](**req.view_args)
  File "/Users/skedzie/Development/learn/python/microblog/venv/lib/python3.8/site-packages/flask_login/utils.py", line 272, in decorated_view
    return func(*args, **kwargs)
  File "/Users/skedzie/Development/learn/python/microblog/app/routes.py", line 87, in user_profile
    raise NameError
NameError
2020-07-16 22:26:06,064 INFO: Microblog startup [in /Users/skedzie/Development/learn/python/microblog/app/__init__.py:46]
2020-07-16 22:26:11,156 ERROR: Exception on /user/steve [GET] [in /Users/skedzie/Development/learn/python/microblog/venv/lib/python3.8/site-packages/flask/app.py:1891]
Traceback (most recent call last):
  File "/Users/skedzie/Development/learn/python/microblog/venv/lib/python3.8/site-packages/flask/app.py", line 2447, in wsgi_app
    response = self.full_dispatch_request()
  File "/Users/skedzie/Development/learn/python/microblog/venv/lib/python3.8/site-packages/flask/app.py", line 1952, in full_dispatch_request
    rv = self.handle_user_exception(e)
  File "/Users/skedzie/Development/learn/python/microblog/venv/lib/python3.8/site-packages/flask/app.py", line 1821, in handle_user_exception
    reraise(exc_type, exc_value, tb)
  File "/Users/skedzie/Development/learn/python/microblog/venv/lib/python3.8/site-packages/flask/_compat.py", line 39, in reraise
    raise value
  File "/Users/skedzie/Development/learn/python/microblog/venv/lib/python3.8/site-packages/flask/app.py", line 1950, in full_dispatch_request
    rv = self.dispatch_request()
  File "/Users/skedzie/Development/learn/python/microblog/venv/lib/python3.8/site-packages/flask/app.py", line 1936, in dispatch_request
    return self.view_functions[rule.endpoint](**req.view_args)
  File "/Users/skedzie/Development/learn/python/microblog/venv/lib/python3.8/site-packages/flask_login/utils.py", line 272, in decorated_view
    return func(*args, **kwargs)
  File "/Users/skedzie/Development/learn/python/microblog/app/routes.py", line 87, in user_profile
    raise NameError
NameError
2020-07-16 22:29:00,379 ERROR: Exception on /user/steve [GET] [in /Users/skedzie/Development/learn/python/microblog/venv/lib/python3.8/site-packages/flask/app.py:1891]
Traceback (most recent call last):
  File "/Users/skedzie/Development/learn/python/microblog/venv/lib/python3.8/site-packages/flask/app.py", line 2447, in wsgi_app
    response = self.full_dispatch_request()
  File "/Users/skedzie/Development/learn/python/microblog/venv/lib/python3.8/site-packages/flask/app.py", line 1952, in full_dispatch_request
    rv = self.handle_user_exception(e)
  File "/Users/skedzie/Development/learn/python/microblog/venv/lib/python3.8/site-packages/flask/app.py", line 1821, in handle_user_exception
    reraise(exc_type, exc_value, tb)
  File "/Users/skedzie/Development/learn/python/microblog/venv/lib/python3.8/site-packages/flask/_compat.py", line 39, in reraise
    raise value
  File "/Users/skedzie/Development/learn/python/microblog/venv/lib/python3.8/site-packages/flask/app.py", line 1950, in full_dispatch_request
    rv = self.dispatch_request()
  File "/Users/skedzie/Development/learn/python/microblog/venv/lib/python3.8/site-packages/flask/app.py", line 1936, in dispatch_request
    return self.view_functions[rule.endpoint](**req.view_args)
  File "/Users/skedzie/Development/learn/python/microblog/venv/lib/python3.8/site-packages/flask_login/utils.py", line 272, in decorated_view
    return func(*args, **kwargs)
  File "/Users/skedzie/Development/learn/python/microblog/app/routes.py", line 87, in user_profile
    user = User.query.filter_by(username=username).first_or_404()
NameError
